[2025-01-17T15:06:35.034+0000] {taskinstance.py:1159} INFO - Dependencies all met for dep_context=non-requeueable deps ti=<TaskInstance: etl_process_with_excel_report.transform_data scheduled__2025-01-16T00:00:00+00:00 [queued]>
[2025-01-17T15:06:35.041+0000] {taskinstance.py:1159} INFO - Dependencies all met for dep_context=requeueable deps ti=<TaskInstance: etl_process_with_excel_report.transform_data scheduled__2025-01-16T00:00:00+00:00 [queued]>
[2025-01-17T15:06:35.042+0000] {taskinstance.py:1361} INFO - Starting attempt 4 of 4
[2025-01-17T15:06:35.053+0000] {taskinstance.py:1382} INFO - Executing <Task(PythonOperator): transform_data> on 2025-01-16 00:00:00+00:00
[2025-01-17T15:06:35.061+0000] {standard_task_runner.py:57} INFO - Started process 314 to run task
[2025-01-17T15:06:35.068+0000] {standard_task_runner.py:84} INFO - Running: ['***', 'tasks', 'run', 'etl_process_with_excel_report', 'transform_data', 'scheduled__2025-01-16T00:00:00+00:00', '--job-id', '30', '--raw', '--subdir', 'DAGS_FOLDER/db_to_xls.py', '--cfg-path', '/tmp/tmpvz16ttll']
[2025-01-17T15:06:35.077+0000] {standard_task_runner.py:85} INFO - Job 30: Subtask transform_data
[2025-01-17T15:06:35.156+0000] {task_command.py:415} INFO - Running <TaskInstance: etl_process_with_excel_report.transform_data scheduled__2025-01-16T00:00:00+00:00 [running]> on host 4e4dfd1b49e6
[2025-01-17T15:06:35.260+0000] {taskinstance.py:1660} INFO - Exporting env vars: AIRFLOW_CTX_DAG_OWNER='***' AIRFLOW_CTX_DAG_ID='etl_process_with_excel_report' AIRFLOW_CTX_TASK_ID='transform_data' AIRFLOW_CTX_EXECUTION_DATE='2025-01-16T00:00:00+00:00' AIRFLOW_CTX_TRY_NUMBER='4' AIRFLOW_CTX_DAG_RUN_ID='scheduled__2025-01-16T00:00:00+00:00'
[2025-01-17T15:06:35.296+0000] {db_to_xls.py:121} ERROR - Error during data transformation: 'Membership_Type'
[2025-01-17T15:06:35.297+0000] {taskinstance.py:1943} ERROR - Task failed with exception
Traceback (most recent call last):
  File "/home/airflow/.local/lib/python3.9/site-packages/pandas/core/indexes/base.py", line 3653, in get_loc
    return self._engine.get_loc(casted_key)
  File "pandas/_libs/index.pyx", line 147, in pandas._libs.index.IndexEngine.get_loc
  File "pandas/_libs/index.pyx", line 176, in pandas._libs.index.IndexEngine.get_loc
  File "pandas/_libs/hashtable_class_helper.pxi", line 7080, in pandas._libs.hashtable.PyObjectHashTable.get_item
  File "pandas/_libs/hashtable_class_helper.pxi", line 7088, in pandas._libs.hashtable.PyObjectHashTable.get_item
KeyError: 'Membership_Type'

The above exception was the direct cause of the following exception:

Traceback (most recent call last):
  File "/home/airflow/.local/lib/python3.9/site-packages/airflow/operators/python.py", line 192, in execute
    return_value = self.execute_callable()
  File "/home/airflow/.local/lib/python3.9/site-packages/airflow/operators/python.py", line 209, in execute_callable
    return self.python_callable(*self.op_args, **self.op_kwargs)
  File "/opt/airflow/dags/db_to_xls.py", line 51, in transform_data
    memberships['Membership_Type'] = memberships['Membership_Type'].replace('', pd.NA)
  File "/home/airflow/.local/lib/python3.9/site-packages/pandas/core/frame.py", line 3761, in __getitem__
    indexer = self.columns.get_loc(key)
  File "/home/airflow/.local/lib/python3.9/site-packages/pandas/core/indexes/base.py", line 3655, in get_loc
    raise KeyError(key) from err
KeyError: 'Membership_Type'
[2025-01-17T15:06:35.318+0000] {taskinstance.py:1400} INFO - Marking task as FAILED. dag_id=etl_process_with_excel_report, task_id=transform_data, execution_date=20250116T000000, start_date=20250117T150635, end_date=20250117T150635
[2025-01-17T15:06:35.332+0000] {standard_task_runner.py:104} ERROR - Failed to execute job 30 for task transform_data ('Membership_Type'; 314)
[2025-01-17T15:06:35.364+0000] {local_task_job_runner.py:228} INFO - Task exited with return code 1
[2025-01-17T15:06:35.390+0000] {taskinstance.py:2784} INFO - 0 downstream tasks scheduled from follow-on schedule check
