[2025-01-17T15:16:42.979+0000] {taskinstance.py:1159} INFO - Dependencies all met for dep_context=non-requeueable deps ti=<TaskInstance: etl_process_with_excel_report.transform_data scheduled__2025-01-16T00:00:00+00:00 [queued]>
[2025-01-17T15:16:42.988+0000] {taskinstance.py:1159} INFO - Dependencies all met for dep_context=requeueable deps ti=<TaskInstance: etl_process_with_excel_report.transform_data scheduled__2025-01-16T00:00:00+00:00 [queued]>
[2025-01-17T15:16:42.989+0000] {taskinstance.py:1361} INFO - Starting attempt 10 of 10
[2025-01-17T15:16:43.001+0000] {taskinstance.py:1382} INFO - Executing <Task(PythonOperator): transform_data> on 2025-01-16 00:00:00+00:00
[2025-01-17T15:16:43.011+0000] {standard_task_runner.py:57} INFO - Started process 470 to run task
[2025-01-17T15:16:43.018+0000] {standard_task_runner.py:84} INFO - Running: ['***', 'tasks', 'run', 'etl_process_with_excel_report', 'transform_data', 'scheduled__2025-01-16T00:00:00+00:00', '--job-id', '36', '--raw', '--subdir', 'DAGS_FOLDER/db_to_xls.py', '--cfg-path', '/tmp/tmpqp8s0259']
[2025-01-17T15:16:43.023+0000] {standard_task_runner.py:85} INFO - Job 36: Subtask transform_data
[2025-01-17T15:16:43.102+0000] {task_command.py:415} INFO - Running <TaskInstance: etl_process_with_excel_report.transform_data scheduled__2025-01-16T00:00:00+00:00 [running]> on host 4e4dfd1b49e6
[2025-01-17T15:16:43.198+0000] {taskinstance.py:1660} INFO - Exporting env vars: AIRFLOW_CTX_DAG_OWNER='***' AIRFLOW_CTX_DAG_ID='etl_process_with_excel_report' AIRFLOW_CTX_TASK_ID='transform_data' AIRFLOW_CTX_EXECUTION_DATE='2025-01-16T00:00:00+00:00' AIRFLOW_CTX_TRY_NUMBER='10' AIRFLOW_CTX_DAG_RUN_ID='scheduled__2025-01-16T00:00:00+00:00'
[2025-01-17T15:16:43.283+0000] {db_to_xls.py:120} ERROR - Error during data transformation: "Column(s) ['effective_amount'] do not exist"
[2025-01-17T15:16:43.284+0000] {taskinstance.py:1943} ERROR - Task failed with exception
Traceback (most recent call last):
  File "/home/airflow/.local/lib/python3.9/site-packages/airflow/operators/python.py", line 192, in execute
    return_value = self.execute_callable()
  File "/home/airflow/.local/lib/python3.9/site-packages/airflow/operators/python.py", line 209, in execute_callable
    return self.python_callable(*self.op_args, **self.op_kwargs)
  File "/opt/airflow/dags/db_to_xls.py", line 91, in transform_data
    daily_activity_report = transactions_with_mdr_df.groupby(transactions_with_mdr_df['timestamp'].dt.date).agg(
  File "/home/airflow/.local/lib/python3.9/site-packages/pandas/core/groupby/generic.py", line 1269, in aggregate
    result = op.agg()
  File "/home/airflow/.local/lib/python3.9/site-packages/pandas/core/apply.py", line 163, in agg
    return self.agg_dict_like()
  File "/home/airflow/.local/lib/python3.9/site-packages/pandas/core/apply.py", line 403, in agg_dict_like
    arg = self.normalize_dictlike_arg("agg", selected_obj, arg)
  File "/home/airflow/.local/lib/python3.9/site-packages/pandas/core/apply.py", line 535, in normalize_dictlike_arg
    raise KeyError(f"Column(s) {cols_sorted} do not exist")
KeyError: "Column(s) ['effective_amount'] do not exist"
[2025-01-17T15:16:43.304+0000] {taskinstance.py:1400} INFO - Marking task as FAILED. dag_id=etl_process_with_excel_report, task_id=transform_data, execution_date=20250116T000000, start_date=20250117T151642, end_date=20250117T151643
[2025-01-17T15:16:43.314+0000] {standard_task_runner.py:104} ERROR - Failed to execute job 36 for task transform_data ("Column(s) ['effective_amount'] do not exist"; 470)
[2025-01-17T15:16:43.352+0000] {local_task_job_runner.py:228} INFO - Task exited with return code 1
[2025-01-17T15:16:43.377+0000] {taskinstance.py:2784} INFO - 0 downstream tasks scheduled from follow-on schedule check
