[2025-01-17T15:16:05.914+0000] {taskinstance.py:1159} INFO - Dependencies all met for dep_context=non-requeueable deps ti=<TaskInstance: etl_process_with_excel_report.transform_data scheduled__2025-01-16T00:00:00+00:00 [queued]>
[2025-01-17T15:16:05.923+0000] {taskinstance.py:1159} INFO - Dependencies all met for dep_context=requeueable deps ti=<TaskInstance: etl_process_with_excel_report.transform_data scheduled__2025-01-16T00:00:00+00:00 [queued]>
[2025-01-17T15:16:05.924+0000] {taskinstance.py:1361} INFO - Starting attempt 9 of 9
[2025-01-17T15:16:05.935+0000] {taskinstance.py:1382} INFO - Executing <Task(PythonOperator): transform_data> on 2025-01-16 00:00:00+00:00
[2025-01-17T15:16:05.941+0000] {standard_task_runner.py:57} INFO - Started process 455 to run task
[2025-01-17T15:16:05.949+0000] {standard_task_runner.py:84} INFO - Running: ['***', 'tasks', 'run', 'etl_process_with_excel_report', 'transform_data', 'scheduled__2025-01-16T00:00:00+00:00', '--job-id', '35', '--raw', '--subdir', 'DAGS_FOLDER/db_to_xls.py', '--cfg-path', '/tmp/tmp17g5zvax']
[2025-01-17T15:16:05.954+0000] {standard_task_runner.py:85} INFO - Job 35: Subtask transform_data
[2025-01-17T15:16:06.033+0000] {task_command.py:415} INFO - Running <TaskInstance: etl_process_with_excel_report.transform_data scheduled__2025-01-16T00:00:00+00:00 [running]> on host 4e4dfd1b49e6
[2025-01-17T15:16:06.132+0000] {taskinstance.py:1660} INFO - Exporting env vars: AIRFLOW_CTX_DAG_OWNER='***' AIRFLOW_CTX_DAG_ID='etl_process_with_excel_report' AIRFLOW_CTX_TASK_ID='transform_data' AIRFLOW_CTX_EXECUTION_DATE='2025-01-16T00:00:00+00:00' AIRFLOW_CTX_TRY_NUMBER='9' AIRFLOW_CTX_DAG_RUN_ID='scheduled__2025-01-16T00:00:00+00:00'
[2025-01-17T15:16:06.206+0000] {db_to_xls.py:120} ERROR - Error during data transformation: 'Name'
[2025-01-17T15:16:06.207+0000] {taskinstance.py:1943} ERROR - Task failed with exception
Traceback (most recent call last):
  File "/home/airflow/.local/lib/python3.9/site-packages/airflow/operators/python.py", line 192, in execute
    return_value = self.execute_callable()
  File "/home/airflow/.local/lib/python3.9/site-packages/airflow/operators/python.py", line 209, in execute_callable
    return self.python_callable(*self.op_args, **self.op_kwargs)
  File "/opt/airflow/dags/db_to_xls.py", line 75, in transform_data
    user_profiling = transactions_with_mdr_df.groupby(['user_id', 'Name', 'timestamp', 'membership_type', 'membership_purchase_status', 'mdr_percentage']).agg(
  File "/home/airflow/.local/lib/python3.9/site-packages/pandas/core/frame.py", line 8252, in groupby
    return DataFrameGroupBy(
  File "/home/airflow/.local/lib/python3.9/site-packages/pandas/core/groupby/groupby.py", line 931, in __init__
    grouper, exclusions, obj = get_grouper(
  File "/home/airflow/.local/lib/python3.9/site-packages/pandas/core/groupby/grouper.py", line 985, in get_grouper
    raise KeyError(gpr)
KeyError: 'Name'
[2025-01-17T15:16:06.228+0000] {taskinstance.py:1400} INFO - Marking task as FAILED. dag_id=etl_process_with_excel_report, task_id=transform_data, execution_date=20250116T000000, start_date=20250117T151605, end_date=20250117T151606
[2025-01-17T15:16:06.239+0000] {standard_task_runner.py:104} ERROR - Failed to execute job 35 for task transform_data ('Name'; 455)
[2025-01-17T15:16:06.299+0000] {local_task_job_runner.py:228} INFO - Task exited with return code 1
[2025-01-17T15:16:06.325+0000] {taskinstance.py:2784} INFO - 0 downstream tasks scheduled from follow-on schedule check
