[2025-01-17T15:09:37.154+0000] {taskinstance.py:1159} INFO - Dependencies all met for dep_context=non-requeueable deps ti=<TaskInstance: etl_process_with_excel_report.transform_data scheduled__2025-01-16T00:00:00+00:00 [queued]>
[2025-01-17T15:09:37.161+0000] {taskinstance.py:1159} INFO - Dependencies all met for dep_context=requeueable deps ti=<TaskInstance: etl_process_with_excel_report.transform_data scheduled__2025-01-16T00:00:00+00:00 [queued]>
[2025-01-17T15:09:37.162+0000] {taskinstance.py:1361} INFO - Starting attempt 7 of 7
[2025-01-17T15:09:37.173+0000] {taskinstance.py:1382} INFO - Executing <Task(PythonOperator): transform_data> on 2025-01-16 00:00:00+00:00
[2025-01-17T15:09:37.180+0000] {standard_task_runner.py:57} INFO - Started process 371 to run task
[2025-01-17T15:09:37.188+0000] {standard_task_runner.py:84} INFO - Running: ['***', 'tasks', 'run', 'etl_process_with_excel_report', 'transform_data', 'scheduled__2025-01-16T00:00:00+00:00', '--job-id', '33', '--raw', '--subdir', 'DAGS_FOLDER/db_to_xls.py', '--cfg-path', '/tmp/tmp26ed7d75']
[2025-01-17T15:09:37.193+0000] {standard_task_runner.py:85} INFO - Job 33: Subtask transform_data
[2025-01-17T15:09:37.273+0000] {task_command.py:415} INFO - Running <TaskInstance: etl_process_with_excel_report.transform_data scheduled__2025-01-16T00:00:00+00:00 [running]> on host 4e4dfd1b49e6
[2025-01-17T15:09:37.372+0000] {taskinstance.py:1660} INFO - Exporting env vars: AIRFLOW_CTX_DAG_OWNER='***' AIRFLOW_CTX_DAG_ID='etl_process_with_excel_report' AIRFLOW_CTX_TASK_ID='transform_data' AIRFLOW_CTX_EXECUTION_DATE='2025-01-16T00:00:00+00:00' AIRFLOW_CTX_TRY_NUMBER='7' AIRFLOW_CTX_DAG_RUN_ID='scheduled__2025-01-16T00:00:00+00:00'
[2025-01-17T15:09:37.407+0000] {db_to_xls.py:120} ERROR - Error during data transformation: 'Timestamp'
[2025-01-17T15:09:37.409+0000] {taskinstance.py:1943} ERROR - Task failed with exception
Traceback (most recent call last):
  File "/home/airflow/.local/lib/python3.9/site-packages/pandas/core/indexes/base.py", line 3653, in get_loc
    return self._engine.get_loc(casted_key)
  File "pandas/_libs/index.pyx", line 147, in pandas._libs.index.IndexEngine.get_loc
  File "pandas/_libs/index.pyx", line 176, in pandas._libs.index.IndexEngine.get_loc
  File "pandas/_libs/hashtable_class_helper.pxi", line 7080, in pandas._libs.hashtable.PyObjectHashTable.get_item
  File "pandas/_libs/hashtable_class_helper.pxi", line 7088, in pandas._libs.hashtable.PyObjectHashTable.get_item
KeyError: 'Timestamp'

The above exception was the direct cause of the following exception:

Traceback (most recent call last):
  File "/home/airflow/.local/lib/python3.9/site-packages/airflow/operators/python.py", line 192, in execute
    return_value = self.execute_callable()
  File "/home/airflow/.local/lib/python3.9/site-packages/airflow/operators/python.py", line 209, in execute_callable
    return self.python_callable(*self.op_args, **self.op_kwargs)
  File "/opt/airflow/dags/db_to_xls.py", line 54, in transform_data
    transactions['Timestamp'] = pd.to_datetime(transactions['Timestamp'])
  File "/home/airflow/.local/lib/python3.9/site-packages/pandas/core/frame.py", line 3761, in __getitem__
    indexer = self.columns.get_loc(key)
  File "/home/airflow/.local/lib/python3.9/site-packages/pandas/core/indexes/base.py", line 3655, in get_loc
    raise KeyError(key) from err
KeyError: 'Timestamp'
[2025-01-17T15:09:37.430+0000] {taskinstance.py:1400} INFO - Marking task as FAILED. dag_id=etl_process_with_excel_report, task_id=transform_data, execution_date=20250116T000000, start_date=20250117T150937, end_date=20250117T150937
[2025-01-17T15:09:37.440+0000] {standard_task_runner.py:104} ERROR - Failed to execute job 33 for task transform_data ('Timestamp'; 371)
[2025-01-17T15:09:37.486+0000] {local_task_job_runner.py:228} INFO - Task exited with return code 1
[2025-01-17T15:09:37.654+0000] {taskinstance.py:2784} INFO - 0 downstream tasks scheduled from follow-on schedule check
