[2025-01-17T14:55:48.710+0000] {taskinstance.py:1159} INFO - Dependencies all met for dep_context=non-requeueable deps ti=<TaskInstance: etl_process_with_excel_report.transform_data scheduled__2025-01-16T00:00:00+00:00 [queued]>
[2025-01-17T14:55:48.724+0000] {taskinstance.py:1159} INFO - Dependencies all met for dep_context=requeueable deps ti=<TaskInstance: etl_process_with_excel_report.transform_data scheduled__2025-01-16T00:00:00+00:00 [queued]>
[2025-01-17T14:55:48.726+0000] {taskinstance.py:1361} INFO - Starting attempt 1 of 1
[2025-01-17T14:55:48.749+0000] {taskinstance.py:1382} INFO - Executing <Task(PythonOperator): transform_data> on 2025-01-16 00:00:00+00:00
[2025-01-17T14:55:48.774+0000] {standard_task_runner.py:57} INFO - Started process 170 to run task
[2025-01-17T14:55:48.793+0000] {standard_task_runner.py:84} INFO - Running: ['***', 'tasks', 'run', 'etl_process_with_excel_report', 'transform_data', 'scheduled__2025-01-16T00:00:00+00:00', '--job-id', '26', '--raw', '--subdir', 'DAGS_FOLDER/db_to_xls.py', '--cfg-path', '/tmp/tmprwhl1bsp']
[2025-01-17T14:55:48.803+0000] {standard_task_runner.py:85} INFO - Job 26: Subtask transform_data
[2025-01-17T14:55:49.086+0000] {task_command.py:415} INFO - Running <TaskInstance: etl_process_with_excel_report.transform_data scheduled__2025-01-16T00:00:00+00:00 [running]> on host 4e4dfd1b49e6
[2025-01-17T14:55:49.348+0000] {taskinstance.py:1660} INFO - Exporting env vars: AIRFLOW_CTX_DAG_OWNER='***' AIRFLOW_CTX_DAG_ID='etl_process_with_excel_report' AIRFLOW_CTX_TASK_ID='transform_data' AIRFLOW_CTX_EXECUTION_DATE='2025-01-16T00:00:00+00:00' AIRFLOW_CTX_TRY_NUMBER='1' AIRFLOW_CTX_DAG_RUN_ID='scheduled__2025-01-16T00:00:00+00:00'
[2025-01-17T14:55:49.423+0000] {db_to_xls.py:120} ERROR - Error during data transformation: ['Membership_Type']
[2025-01-17T14:55:49.425+0000] {taskinstance.py:1943} ERROR - Task failed with exception
Traceback (most recent call last):
  File "/home/airflow/.local/lib/python3.9/site-packages/airflow/operators/python.py", line 192, in execute
    return_value = self.execute_callable()
  File "/home/airflow/.local/lib/python3.9/site-packages/airflow/operators/python.py", line 209, in execute_callable
    return self.python_callable(*self.op_args, **self.op_kwargs)
  File "/opt/airflow/dags/db_to_xls.py", line 51, in transform_data
    memberships.dropna(subset=['Membership_Type'], inplace=True)
  File "/home/airflow/.local/lib/python3.9/site-packages/pandas/core/frame.py", line 6407, in dropna
    raise KeyError(np.array(subset)[check].tolist())
KeyError: ['Membership_Type']
[2025-01-17T14:55:49.450+0000] {taskinstance.py:1400} INFO - Marking task as FAILED. dag_id=etl_process_with_excel_report, task_id=transform_data, execution_date=20250116T000000, start_date=20250117T145548, end_date=20250117T145549
[2025-01-17T14:55:49.467+0000] {standard_task_runner.py:104} ERROR - Failed to execute job 26 for task transform_data (['Membership_Type']; 170)
[2025-01-17T14:55:49.500+0000] {local_task_job_runner.py:228} INFO - Task exited with return code 1
[2025-01-17T14:55:49.553+0000] {taskinstance.py:2784} INFO - 0 downstream tasks scheduled from follow-on schedule check
