[2025-01-17T15:17:42.070+0000] {taskinstance.py:1159} INFO - Dependencies all met for dep_context=non-requeueable deps ti=<TaskInstance: etl_process_with_excel_report.load_data scheduled__2025-01-16T00:00:00+00:00 [queued]>
[2025-01-17T15:17:42.081+0000] {taskinstance.py:1159} INFO - Dependencies all met for dep_context=requeueable deps ti=<TaskInstance: etl_process_with_excel_report.load_data scheduled__2025-01-16T00:00:00+00:00 [queued]>
[2025-01-17T15:17:42.082+0000] {taskinstance.py:1361} INFO - Starting attempt 1 of 1
[2025-01-17T15:17:42.098+0000] {taskinstance.py:1382} INFO - Executing <Task(PythonOperator): load_data> on 2025-01-16 00:00:00+00:00
[2025-01-17T15:17:42.110+0000] {standard_task_runner.py:57} INFO - Started process 488 to run task
[2025-01-17T15:17:42.118+0000] {standard_task_runner.py:84} INFO - Running: ['***', 'tasks', 'run', 'etl_process_with_excel_report', 'load_data', 'scheduled__2025-01-16T00:00:00+00:00', '--job-id', '38', '--raw', '--subdir', 'DAGS_FOLDER/db_to_xls.py', '--cfg-path', '/tmp/tmph0xhco2k']
[2025-01-17T15:17:42.124+0000] {standard_task_runner.py:85} INFO - Job 38: Subtask load_data
[2025-01-17T15:17:42.199+0000] {task_command.py:415} INFO - Running <TaskInstance: etl_process_with_excel_report.load_data scheduled__2025-01-16T00:00:00+00:00 [running]> on host 4e4dfd1b49e6
[2025-01-17T15:17:42.296+0000] {taskinstance.py:1660} INFO - Exporting env vars: AIRFLOW_CTX_DAG_OWNER='***' AIRFLOW_CTX_DAG_ID='etl_process_with_excel_report' AIRFLOW_CTX_TASK_ID='load_data' AIRFLOW_CTX_EXECUTION_DATE='2025-01-16T00:00:00+00:00' AIRFLOW_CTX_TRY_NUMBER='1' AIRFLOW_CTX_DAG_RUN_ID='scheduled__2025-01-16T00:00:00+00:00'
[2025-01-17T15:17:42.415+0000] {base.py:73} INFO - Using connection ID 'local_***' for task execution.
[2025-01-17T15:17:42.467+0000] {db_to_xls.py:169} ERROR - Error during data loading: can't adapt type 'numpy.int64'
[2025-01-17T15:17:42.468+0000] {taskinstance.py:1943} ERROR - Task failed with exception
Traceback (most recent call last):
  File "/home/airflow/.local/lib/python3.9/site-packages/airflow/operators/python.py", line 192, in execute
    return_value = self.execute_callable()
  File "/home/airflow/.local/lib/python3.9/site-packages/airflow/operators/python.py", line 209, in execute_callable
    return self.python_callable(*self.op_args, **self.op_kwargs)
  File "/opt/airflow/dags/db_to_xls.py", line 140, in load_data
    postgres_hook.insert_rows(
  File "/home/airflow/.local/lib/python3.9/site-packages/airflow/providers/common/sql/hooks/sql.py", line 509, in insert_rows
    cur.execute(sql, values)
psycopg2.ProgrammingError: can't adapt type 'numpy.int64'
[2025-01-17T15:17:42.485+0000] {taskinstance.py:1400} INFO - Marking task as FAILED. dag_id=etl_process_with_excel_report, task_id=load_data, execution_date=20250116T000000, start_date=20250117T151742, end_date=20250117T151742
[2025-01-17T15:17:42.496+0000] {standard_task_runner.py:104} ERROR - Failed to execute job 38 for task load_data (can't adapt type 'numpy.int64'; 488)
[2025-01-17T15:17:42.538+0000] {local_task_job_runner.py:228} INFO - Task exited with return code 1
[2025-01-17T15:17:42.563+0000] {taskinstance.py:2784} INFO - 0 downstream tasks scheduled from follow-on schedule check
