[2025-01-17T17:46:39.750+0000] {taskinstance.py:1159} INFO - Dependencies all met for dep_context=non-requeueable deps ti=<TaskInstance: etl_process_with_excel_report.generate_excel_report manual__2025-01-17T17:24:34.119787+00:00 [queued]>
[2025-01-17T17:46:39.757+0000] {taskinstance.py:1159} INFO - Dependencies all met for dep_context=requeueable deps ti=<TaskInstance: etl_process_with_excel_report.generate_excel_report manual__2025-01-17T17:24:34.119787+00:00 [queued]>
[2025-01-17T17:46:39.757+0000] {taskinstance.py:1361} INFO - Starting attempt 1 of 1
[2025-01-17T17:46:39.768+0000] {taskinstance.py:1382} INFO - Executing <Task(PythonOperator): generate_excel_report> on 2025-01-17 17:24:34.119787+00:00
[2025-01-17T17:46:39.782+0000] {standard_task_runner.py:57} INFO - Started process 540 to run task
[2025-01-17T17:46:39.792+0000] {standard_task_runner.py:84} INFO - Running: ['***', 'tasks', 'run', 'etl_process_with_excel_report', 'generate_excel_report', 'manual__2025-01-17T17:24:34.119787+00:00', '--job-id', '74', '--raw', '--subdir', 'DAGS_FOLDER/db_to_xls.py', '--cfg-path', '/tmp/tmpgzq924x0']
[2025-01-17T17:46:39.874+0000] {standard_task_runner.py:85} INFO - Job 74: Subtask generate_excel_report
[2025-01-17T17:46:40.195+0000] {task_command.py:415} INFO - Running <TaskInstance: etl_process_with_excel_report.generate_excel_report manual__2025-01-17T17:24:34.119787+00:00 [running]> on host e075edadbc7d
[2025-01-17T17:46:40.640+0000] {taskinstance.py:1660} INFO - Exporting env vars: AIRFLOW_CTX_DAG_OWNER='***' AIRFLOW_CTX_DAG_ID='etl_process_with_excel_report' AIRFLOW_CTX_TASK_ID='generate_excel_report' AIRFLOW_CTX_EXECUTION_DATE='2025-01-17T17:24:34.119787+00:00' AIRFLOW_CTX_TRY_NUMBER='1' AIRFLOW_CTX_DAG_RUN_ID='manual__2025-01-17T17:24:34.119787+00:00'
[2025-01-17T17:46:40.793+0000] {base.py:73} INFO - Using connection ID 'local_***' for task execution.
[2025-01-17T17:46:40.949+0000] {logging_mixin.py:151} WARNING - /home/***/.local/lib/python3.9/site-packages/***/providers/common/sql/hooks/sql.py:219 UserWarning: pandas only supports SQLAlchemy connectable (engine/connection) or database string URI or sqlite3 DBAPI2 connection. Other DBAPI2 objects are not tested. Please consider using SQLAlchemy.
[2025-01-17T17:46:41.039+0000] {base.py:73} INFO - Using connection ID 'local_***' for task execution.
[2025-01-17T17:46:41.136+0000] {base.py:73} INFO - Using connection ID 'local_***' for task execution.
[2025-01-17T17:46:41.232+0000] {base.py:73} INFO - Using connection ID 'local_***' for task execution.
[2025-01-17T17:46:41.309+0000] {db_to_xls.py:319} ERROR - Error generating Excel report: No module named 'xlsxwriter'
[2025-01-17T17:46:41.311+0000] {taskinstance.py:1943} ERROR - Task failed with exception
Traceback (most recent call last):
  File "/home/airflow/.local/lib/python3.9/site-packages/airflow/operators/python.py", line 192, in execute
    return_value = self.execute_callable()
  File "/home/airflow/.local/lib/python3.9/site-packages/airflow/operators/python.py", line 209, in execute_callable
    return self.python_callable(*self.op_args, **self.op_kwargs)
  File "/opt/airflow/dags/db_to_xls.py", line 311, in generate_excel_report
    with pd.ExcelWriter(report_file_path, engine='xlsxwriter') as writer:
  File "/home/airflow/.local/lib/python3.9/site-packages/pandas/io/excel/_xlsxwriter.py", line 192, in __init__
    from xlsxwriter import Workbook
ModuleNotFoundError: No module named 'xlsxwriter'
[2025-01-17T17:46:41.387+0000] {taskinstance.py:1400} INFO - Marking task as FAILED. dag_id=etl_process_with_excel_report, task_id=generate_excel_report, execution_date=20250117T172434, start_date=20250117T174639, end_date=20250117T174641
[2025-01-17T17:46:41.409+0000] {standard_task_runner.py:104} ERROR - Failed to execute job 74 for task generate_excel_report (No module named 'xlsxwriter'; 540)
[2025-01-17T17:46:41.619+0000] {local_task_job_runner.py:228} INFO - Task exited with return code 1
[2025-01-17T17:46:41.771+0000] {taskinstance.py:2784} INFO - 0 downstream tasks scheduled from follow-on schedule check
