[2025-01-29T10:21:55.218+0000] {taskinstance.py:1159} INFO - Dependencies all met for dep_context=non-requeueable deps ti=<TaskInstance: load_raw_data.load_csv_to_postgres scheduled__2025-01-28T00:00:00+00:00 [queued]>
[2025-01-29T10:21:55.811+0000] {taskinstance.py:1159} INFO - Dependencies all met for dep_context=requeueable deps ti=<TaskInstance: load_raw_data.load_csv_to_postgres scheduled__2025-01-28T00:00:00+00:00 [queued]>
[2025-01-29T10:21:55.828+0000] {taskinstance.py:1361} INFO - Starting attempt 1 of 1
[2025-01-29T10:21:55.945+0000] {taskinstance.py:1382} INFO - Executing <Task(PythonOperator): load_csv_to_postgres> on 2025-01-28 00:00:00+00:00
[2025-01-29T10:21:56.099+0000] {standard_task_runner.py:57} INFO - Started process 279 to run task
[2025-01-29T10:21:56.153+0000] {standard_task_runner.py:84} INFO - Running: ['***', 'tasks', 'run', 'load_raw_data', 'load_csv_to_postgres', 'scheduled__2025-01-28T00:00:00+00:00', '--job-id', '2', '--raw', '--subdir', 'DAGS_FOLDER/etl_dag.py', '--cfg-path', '/tmp/tmpq4xvnwi7']
[2025-01-29T10:21:56.213+0000] {standard_task_runner.py:85} INFO - Job 2: Subtask load_csv_to_postgres
[2025-01-29T10:21:57.397+0000] {task_command.py:415} INFO - Running <TaskInstance: load_raw_data.load_csv_to_postgres scheduled__2025-01-28T00:00:00+00:00 [running]> on host 08d824b63153
[2025-01-29T10:21:59.058+0000] {taskinstance.py:1660} INFO - Exporting env vars: AIRFLOW_CTX_DAG_OWNER='***' AIRFLOW_CTX_DAG_ID='load_raw_data' AIRFLOW_CTX_TASK_ID='load_csv_to_postgres' AIRFLOW_CTX_EXECUTION_DATE='2025-01-28T00:00:00+00:00' AIRFLOW_CTX_TRY_NUMBER='1' AIRFLOW_CTX_DAG_RUN_ID='scheduled__2025-01-28T00:00:00+00:00'
[2025-01-29T10:21:59.479+0000] {base.py:73} INFO - Using connection ID 'local_***' for task execution.
[2025-01-29T10:21:59.539+0000] {taskinstance.py:1943} ERROR - Task failed with exception
Traceback (most recent call last):
  File "/home/airflow/.local/lib/python3.9/site-packages/airflow/operators/python.py", line 192, in execute
    return_value = self.execute_callable()
  File "/home/airflow/.local/lib/python3.9/site-packages/airflow/operators/python.py", line 209, in execute_callable
    return self.python_callable(*self.op_args, **self.op_kwargs)
  File "/opt/airflow/dags/etl_dag.py", line 39, in load_raw_data
    df = pd.read_csv(file_path)
  File "/home/airflow/.local/lib/python3.9/site-packages/pandas/io/parsers/readers.py", line 912, in read_csv
    return _read(filepath_or_buffer, kwds)
  File "/home/airflow/.local/lib/python3.9/site-packages/pandas/io/parsers/readers.py", line 577, in _read
    parser = TextFileReader(filepath_or_buffer, **kwds)
  File "/home/airflow/.local/lib/python3.9/site-packages/pandas/io/parsers/readers.py", line 1407, in __init__
    self._engine = self._make_engine(f, self.engine)
  File "/home/airflow/.local/lib/python3.9/site-packages/pandas/io/parsers/readers.py", line 1661, in _make_engine
    self.handles = get_handle(
  File "/home/airflow/.local/lib/python3.9/site-packages/pandas/io/common.py", line 859, in get_handle
    handle = open(
FileNotFoundError: [Errno 2] No such file or directory: '/mnt/data/customers_dataset.csv'
[2025-01-29T10:21:59.652+0000] {taskinstance.py:1400} INFO - Marking task as FAILED. dag_id=load_raw_data, task_id=load_csv_to_***, execution_date=20250128T000000, start_date=20250129T102155, end_date=20250129T102159
[2025-01-29T10:21:59.737+0000] {standard_task_runner.py:104} ERROR - Failed to execute job 2 for task load_csv_to_*** ([Errno 2] No such file or directory: '/mnt/data/customers_dataset.csv'; 279)
[2025-01-29T10:22:00.105+0000] {local_task_job_runner.py:228} INFO - Task exited with return code 1
[2025-01-29T10:22:00.516+0000] {taskinstance.py:2784} INFO - 0 downstream tasks scheduled from follow-on schedule check
